2022-01-14 03:45:40,183:ERROR:src.ETL:upload_transformed_data_to_azure:there is problem uploading transformed data to azure blob storage
Traceback (most recent call last):
  File "/Users/mantas/PycharmProjects/makaw_assesment/makaw_assesment/src/ETL.py", line 156, in upload_transformed_data_to_azure
    self.blob_service_client.create_container(container_name)
  File "/Users/mantas/PycharmProjects/makaw_assesment/makaw_assesment/.venv/lib/python3.9/site-packages/azure/core/tracing/decorator.py", line 83, in wrapper_use_tracer
    return func(*args, **kwargs)
  File "/Users/mantas/PycharmProjects/makaw_assesment/makaw_assesment/.venv/lib/python3.9/site-packages/azure/storage/blob/_blob_service_client.py", line 518, in create_container
    container.create_container(
  File "/Users/mantas/PycharmProjects/makaw_assesment/makaw_assesment/.venv/lib/python3.9/site-packages/azure/core/tracing/decorator.py", line 83, in wrapper_use_tracer
    return func(*args, **kwargs)
  File "/Users/mantas/PycharmProjects/makaw_assesment/makaw_assesment/.venv/lib/python3.9/site-packages/azure/storage/blob/_container_client.py", line 299, in create_container
    process_storage_error(error)
  File "/Users/mantas/PycharmProjects/makaw_assesment/makaw_assesment/.venv/lib/python3.9/site-packages/azure/storage/blob/_shared/response_handlers.py", line 177, in process_storage_error
    exec("raise error from None")   # pylint: disable=exec-used # nosec
  File "<string>", line 1, in <module>
  File "/Users/mantas/PycharmProjects/makaw_assesment/makaw_assesment/.venv/lib/python3.9/site-packages/azure/storage/blob/_container_client.py", line 291, in create_container
    return self._client.container.create( # type: ignore
  File "/Users/mantas/PycharmProjects/makaw_assesment/makaw_assesment/.venv/lib/python3.9/site-packages/azure/storage/blob/_generated/operations/_container_operations.py", line 133, in create
    map_error(status_code=response.status_code, response=response, error_map=error_map)
  File "/Users/mantas/PycharmProjects/makaw_assesment/makaw_assesment/.venv/lib/python3.9/site-packages/azure/core/exceptions.py", line 105, in map_error
    raise error
azure.core.exceptions.ResourceExistsError: The specified container already exists.
RequestId:174f3132-701e-0032-32e8-081ec1000000
Time:2022-01-14T01:45:40.1309347Z
ErrorCode:ContainerAlreadyExists
